<?xml version="1.0" ?>
<!-- =================================================================================== -->
<!-- |    This document was autogenerated by xacro from awesome_leg_standalone.urdf.xacro | -->
<!-- |    EDITING THIS FILE BY HAND IS NOT RECOMMENDED                                 | -->
<!-- =================================================================================== -->
<!-- 
    Leg base URDF (no external links). Variant of the URDF adapted for use with Pinocchio and for performing inertial parameter identification 
-->
<robot name="awesome_leg">
  <!-- <xacro:property name="payload_mass" value="7.38" /> -->
  <!-- color -->
  <material name="darkblue">
    <color rgba="0.0 0.3 0.9 1"/>
  </material>
  <material name="dark">
    <color rgba="0.6 0.6 0.6 1"/>
  </material>
  <material name="sky_blue">
    <color rgba="0.13 0.44 0.70 1"/>
  </material>
  <material name="grey">
    <color rgba=" 0.6 0.6 0.6 1"/>
  </material>
  <material name="black">
    <color rgba="0.4 0.4 0.4 1"/>
  </material>
  <material name="brown">
    <color rgba="0.59 0.29 0.0 1"/>
  </material>
  <!-- <xacro:property name="payload_mass" value="7.38" /> -->
  <!-- color -->
  <material name="darkblue">
    <color rgba="0.0 0.3 0.9 1"/>
  </material>
  <material name="dark">
    <color rgba="0.6 0.6 0.6 1"/>
  </material>
  <material name="sky_blue">
    <color rgba="0.13 0.44 0.70 1"/>
  </material>
  <material name="grey">
    <color rgba=" 0.6 0.6 0.6 1"/>
  </material>
  <material name="black">
    <color rgba="0.4 0.4 0.4 1"/>
  </material>
  <material name="brown">
    <color rgba="0.59 0.29 0.0 1"/>
  </material>
  <!-- xbot2 joint device driver-->
  <gazebo>
    <plugin filename="libxbot2_gz_joint_server.so" name="xbot2_gz_joint_server">
      <pid>
        <gain d="0" name="null_mode" p="0"/>
        <gain d="5" name="small_mot" p="250"/>
        <gain d="10" name="medium_mot" p="1000"/>
        <gain d="10" name="big_mot" p="3000"/>
        <gain name="test_rig2HIP" profile="null_mode"/>
        <gain name="hip_actuation" profile="medium_mot"/>
        <gain name="knee_actuation" profile="medium_mot"/>
      </pid>
    </plugin>
  </gazebo>
  <gazebo>
    <plugin filename="libxbot2_gz_ft_server.so" name="xbot2_ft_driver"/>
  </gazebo>
  <link name="femur1">
    <inertial>
      <origin xyz="0.0 0.0 0.0"/>
      <mass value="3.3712777"/>
      <inertia ixx="0.046647423" ixy="-1.269764e-05" ixz="-3.2745809999999995e-05" iyy="0.043720135" iyz="-0.063299091" izz="0.07579481299999999"/>
    </inertial>
    <visual>
      <origin rpy="0.0 0.0 0.0" xyz="0.0 0.0 0.0"/>
      <geometry>
        <mesh filename="package://awesome_leg/description/new_meshes/visual/femur.stl" scale="0.1 0.1 0.1"/>
      </geometry>
      <material name="darkblue"/>
    </visual>
    <collision>
      <origin rpy="0.0 0.0 0.0" xyz="0.0 0.0 0.0"/>
      <geometry>
        <mesh filename="package://awesome_leg/description/new_meshes/collision/femur.stl" scale="0.1 0.1 0.1"/>
      </geometry>
    </collision>
  </link>
  <joint name="knee_pitch1" type="revolute">
    <parent link="femur1"/>
    <child link="shin1"/>
    <origin rpy="0.0 0.0 0.0" xyz="0.0 -0.1182 -0.3"/>
    <axis xyz="0 1 0"/>
    <limit effort="112" lower="-2.4" upper="2.4" velocity="20.0"/>
  </joint>
  <link name="shin1">
    <inertial>
      <origin xyz="0.0 0.0 0.0"/>
      <mass value="1.3106594"/>
      <inertia ixx="0.040133964999999994" ixy="4.6219082e-08" ixz="-3.043232e-07" iyy="0.040269285" iyz="0.0013816329" izz="0.0015274496"/>
    </inertial>
    <visual>
      <origin rpy="0.0 0.0 0.0" xyz="0.0 0.0 0.0"/>
      <geometry>
        <mesh filename="package://awesome_leg/description/new_meshes/visual/shin.stl" scale="0.1 0.1 0.1"/>
      </geometry>
      <material name="grey"/>
    </visual>
    <collision>
      <origin rpy="0.0 0.0 0.0" xyz="0.0 0.0 0.0"/>
      <geometry>
        <mesh filename="package://awesome_leg/description/new_meshes/collision/shin.stl" scale="0.1 0.1 0.1"/>
      </geometry>
    </collision>
  </link>
  <joint name="tip_joint1" type="fixed">
    <parent link="shin1"/>
    <child link="tip1"/>
    <origin xyz="0.0 0.0233 -0.451"/>
  </joint>
  <link name="tip1"/>
  <!-- <transmission name="hip_pitch${id}">
            <type>transmission_interface/SimpleTransmission</type>
            <joint name="hip_pitch_1">
                <hardwareInterface>hardware_interface/EffortJointInterface</hardwareInterface>
            </joint>
            <actuator name="hip_motor">
                <hardwareInterface>hardware_interface/EffortJointInterface</hardwareInterface>
                <mechanicalReduction>1</mechanicalReduction>
            </actuator>
        </transmission>
        <transmission name="knee_trans">
            <type>transmission_interface/SimpleTransmission</type>
            <joint name="knee_pitch_1">
                <hardwareInterface>hardware_interface/EffortJointInterface</hardwareInterface>
            </joint>
            <actuator name="knee_motor">
                <hardwareInterface>hardware_interface/EffortJointInterface</hardwareInterface>
                <mechanicalReduction>1</mechanicalReduction>
            </actuator>
        </transmission> -->
</robot>
