<?xml version="1.0" ?>
<!-- =================================================================================== -->
<!-- |    This document was autogenerated by xacro from awesome_leg_reduced.urdf.xacro | -->
<!-- |    EDITING THIS FILE BY HAND IS NOT RECOMMENDED                                 | -->
<!-- =================================================================================== -->
<!-- 
    Leg base URDF (no external links). Variant of the URDF adapted for use with Pinocchio and for performing inertial parameter identification 
-->
<robot name="awesome_leg">
  <!-- color -->
  <material name="darkblue">
    <color rgba="0.0 0.3 0.9 1"/>
  </material>
  <material name="dark">
    <color rgba="0.6 0.6 0.6 1"/>
  </material>
  <material name="sky_blue">
    <color rgba="0.13 0.44 0.70 1"/>
  </material>
  <material name="grey">
    <color rgba=" 0.6 0.6 0.6 1"/>
  </material>
  <material name="black">
    <color rgba="0.4 0.4 0.4 1"/>
  </material>
  <material name="brown">
    <color rgba="0.59 0.29 0.0 1"/>
  </material>
  <link name="pelvis"/>
  <joint name="hip_pitch_1" type="revolute">
    <parent link="pelvis"/>
    <child link="shank"/>
    <origin rpy="-1.57079632679 0 0" xyz="0.0 0.0 0.0"/>
    <axis xyz="0 0 1"/>
    <limit effort="112" lower="-2.0226" upper="2.02748" velocity="20.0"/>
  </joint>
  <link name="shank">
    <inertial>
      <origin xyz="2.57966e-05 0.1810266 0.085669756"/>
      <mass value="2.7264471"/>
      <inertia ixx="0.04851869" ixy="-4.11894e-05" ixz="-1.68778e-05" iyy="0.004242055" iyz="0.0032243188" izz="0.04825583"/>
    </inertial>
    <visual>
      <origin rpy="0.0 0.0 0.0" xyz="0.0 0.0 0.0"/>
      <material name="sky_blue"/>
      <geometry>
        <mesh filename="package://awesome_leg/description/meshes/visual/hip-pitch.stl" scale="0.001 0.001 0.001"/>
      </geometry>
    </visual>
    <collision>
      <origin rpy="0.0 0.0 0.0" xyz="0.0 0.0 0.0"/>
      <geometry>
        <mesh filename="package://awesome_leg/description/meshes/collision/hip-pitch.stl" scale="0.001 0.001 0.001"/>
      </geometry>
    </collision>
  </link>
  <joint name="knee_pitch_1" type="revolute">
    <parent link="shank"/>
    <child link="shin"/>
    <origin rpy="3.14159265359 0.0 1.57079632679" xyz="0.0 0.3 -0.0036"/>
    <axis xyz="0 0 1"/>
    grey
        
    <limit effort="112" lower="-2.0226" upper="2.02748" velocity="20.0"/>
  </joint>
  <link name="shin">
    <inertial>
      <mass value="1.1927236"/>
      <origin xyz="0.19572282 -0.014549221 -0.020785942"/>
      <inertia ixx="0.0013302597" ixy="0.00060307457" ixz="0.0" iyy="0.035313402" iyz="-1.1029574e-07" izz="0.035530025"/>
    </inertial>
    <visual>
      <origin rpy="1.57079632679 0 -1.57079632679" xyz="0 0 0"/>
      <material name="grey"/>
      <geometry name="1_stick_visual">
        <mesh filename="package://awesome_leg/description/meshes/visual/front_right_stick.stl" scale="0.001 0.001 0.001"/>
      </geometry>
    </visual>
    <collision name="foot_tip_collision">
      <origin rpy="1.57079632679 0 -1.57079632679" xyz="0 0 0"/>
      <geometry name="1_stick_collision">
        <mesh filename="package://awesome_leg/description/meshes/collision/front_right_stick.stl" scale="0.001 0.001 0.001"/>
      </geometry>
    </collision>
  </link>
  <joint name="tip_joint" type="fixed">
    <parent link="shin"/>
    <child link="tip"/>
    <origin xyz="0.45 0.0 -0.02"/>
  </joint>
  <link name="tip">
    </link>
  <transmission name="hip_trans">
    <type>transmission_interface/SimpleTransmission</type>
    <joint name="hip_pitch_1">
      <hardwareInterface>hardware_interface/EffortJointInterface</hardwareInterface>
    </joint>
    <actuator name="hip_motor">
      <hardwareInterface>hardware_interface/EffortJointInterface</hardwareInterface>
      <mechanicalReduction>1</mechanicalReduction>
    </actuator>
  </transmission>
  <transmission name="knee_trans">
    <type>transmission_interface/SimpleTransmission</type>
    <joint name="knee_pitch_1">
      <hardwareInterface>hardware_interface/EffortJointInterface</hardwareInterface>
    </joint>
    <actuator name="knee_motor">
      <hardwareInterface>hardware_interface/EffortJointInterface</hardwareInterface>
      <mechanicalReduction>1</mechanicalReduction>
    </actuator>
  </transmission>
  <!-- xbot2 joint device driver-->
  <gazebo>
    <plugin filename="libxbot2_gz_joint_server.so" name="xbot2_gz_joint_server">
      <pid>
        <gain d="0" name="null_mode" p="0"/>
        <gain d="5" name="small_mot" p="250"/>
        <gain d="10" name="medium_mot" p="1000"/>
        <gain d="10" name="big_mot" p="3000"/>
        <gain name="test_rig2HIP" profile="null_mode"/>
        <gain name="hip_actuation" profile="medium_mot"/>
        <gain name="knee_actuation" profile="medium_mot"/>
      </pid>
    </plugin>
  </gazebo>
  <gazebo>
    <plugin filename="libxbot2_gz_ft_server.so" name="xbot2_ft_driver"/>
  </gazebo>
  <!--Gazebo-specific tags-->
  <gazebo reference="pelvis">
    <material>Gazebo/Grey  </material>
  </gazebo>
  <gazebo reference="hip1_1">
    <material>Gazebo/Grey   </material>
  </gazebo>
  <gazebo reference="hip2_1">
    <material>Gazebo/SkyBlue </material>
  </gazebo>
  <gazebo reference="knee_1">
    <material>Gazebo/Grey  </material>
  </gazebo>
</robot>
