<?xml version="1.0" encoding="utf-8" ?>

<!-- Leg base URDF (no external links). Variant of the URDF adapted for use with Pinocchio -->

<robot name="awesome_leg" xmlns:xacro="http://www.ros.org/wiki/xacro">

    <!-- ################### MATERIAL DEFINITIONS ################### -->

    <material name="sky_blue">
        <color rgba="0.13 0.44 0.70 1"/>
    </material>
    <material name="grey">
        <color rgba=" 0.6 0.6 0.6 1"/>
    </material>
    <material name="black">
        <color rgba="0.4 0.4 0.4 1"/>
    </material>
    <material name="brown">
        <color rgba="0.59 0.29 0.0 1"/>
    </material>
    
    <!-- ################### LINKS ################### -->
    <link name="world"/>

    <link name="shank">
        <inertial>
        <origin xyz="2.02539722e-03 2.36232975e-01 8.56697560e-02"/>
        <mass value="2.7264471"/>
        <inertia ixx="0.04851869" ixy="-4.11894e-05" ixz="-1.68778e-05" iyy="0.004242055" iyz="0.0032243188" izz="0.04825583"/>
        </inertial>
        <visual>
        <origin rpy="0.0 0.0 0.0" xyz="0.0 0.0 0.0"/>
        <material name="sky_blue"/>
        <geometry>
            <mesh filename="package://awesome_leg_pholus/description/meshes/visual/hip-pitch.stl" scale="0.001 0.001 0.001"/>
        </geometry>
        </visual>
        <collision>
        <origin rpy="0.0 0.0 0.0" xyz="0.0 0.0 0.0"/>
        <geometry>
            <mesh filename="package://awesome_leg_pholus/description/meshes/collision/hip-pitch.stl" scale="0.001 0.001 0.001"/>
        </geometry>
        </collision>
    </link>

    <link name="shin">
        <inertial>
        <mass value="1.23787877e+00"/>
        <origin xyz="1.52366156e-01 -3.92736885e-04 -2.00277153e-02"/>
        <inertia ixx="0.0013302597" ixy="0.00060307457" ixz="0.0" iyy="0.035313402" iyz="-1.1029574e-07" izz="0.035530025"/>
        </inertial>
        <visual>
        <origin rpy="1.57079632679 0 -1.57079632679" xyz="0 0 0"/>
        <material name="grey"/>
        <geometry name="1_stick_visual">
            <mesh filename="package://awesome_leg_pholus/description/meshes/visual/front_right_stick.stl" scale="0.001 0.001 0.001"/>
        </geometry>
        </visual>
        <collision name="foot_tip_collision">
        <origin rpy="1.57079632679 0 -1.57079632679" xyz="0 0 0"/>
        <geometry name="1_stick_collision">
            <mesh filename="package://awesome_leg_pholus/description/meshes/collision/front_right_stick.stl" scale="0.001 0.001 0.001"/>
        </geometry>
        </collision>
    </link>

    <link name="tip">
    </link>
    
    <!-- ################### JOINTS ################### -->

    <joint name="hip_pitch_1" type="revolute">
        <parent link="world"/>
        <child link="shank"/>
        <origin rpy="-1.57 0 0" xyz="0.0 0.0 0.0"/>
        <axis xyz="0 0 1"/>
        <limit effort="112" lower="-2.0226" upper="2.02748" velocity="20.0"/>
    </joint>

    <joint name="knee_pitch_1" type="revolute">
        <parent link="shank"/>
        <child link="shin"/>
        <origin rpy="3.14159265359 0.0 1.57079632679" xyz="0.0 0.3 -0.0036"/>
        <axis xyz="0 0 1"/>grey
        <limit effort="112" lower="-2.0226" upper="2.02748" velocity="20.0"/>
    </joint>
    
    <joint name="tip_joint" type="fixed">
        <parent link="shin"/>
        <child link="tip"/>
        <origin xyz="0.45 0.0 -0.02"/>
    </joint>
    <!-- ################### TRANSMISSION ELEMENTS ################### -->

   
    <transmission name="hip_trans">
        <type>transmission_interface/SimpleTransmission</type>
        <joint name="hip_pitch_1">
            <hardwareInterface>hardware_interface/EffortJointInterface</hardwareInterface>
        </joint>
        <actuator name="hip_motor">
            <hardwareInterface>hardware_interface/EffortJointInterface</hardwareInterface>
            <mechanicalReduction>1</mechanicalReduction>
        </actuator>
    </transmission>
    <transmission name="knee_trans">
        <type>transmission_interface/SimpleTransmission</type>
        <joint name="knee_pitch_1">
            <hardwareInterface>hardware_interface/EffortJointInterface</hardwareInterface>
        </joint>
        <actuator name="knee_motor">
            <hardwareInterface>hardware_interface/EffortJointInterface</hardwareInterface>
            <mechanicalReduction>1</mechanicalReduction>
        </actuator>
    </transmission>

    <!-- ################### MODEL PLUGINS ################### -->

    <gazebo> <!-- Gazebo-ROS control interface -->
        <plugin name="gazebo_ros_control" filename="libgazebo_ros_control.so"> 
            <robotNamespace>/awesome_leg</robotNamespace>
            <controlPeriod>0.01 </controlPeriod>
            <robotParam> /robot_description </robotParam> 
        </plugin>
    </gazebo>

    <!-- xbot2 joint device driver-->
    <gazebo>  
        <plugin name='xbot2_gz_joint_server' filename='libxbot2_gz_joint_server.so'> 
            <pid>

                <gain name="null_mode"  p="0"  d="0"/>
                <gain name="small_mot"  p="250"  d="5"/>
                <gain name="medium_mot" p="1000" d="10"/>
                <gain name="big_mot"    p="3000" d="10"/>

                <gain name="test_rig2HIP" profile="null_mode"/>
                <gain name="hip_actuation" profile="medium_mot"/>
                <gain name="knee_actuation" profile="medium_mot"/>
            </pid>
        </plugin>
    </gazebo>

    <gazebo> 
        <plugin name="xbot2_ft_driver" filename="libxbot2_gz_ft_server.so"/>
    </gazebo>
    

    <!-- ################### OTHER STUFF ################### -->

    <!--Gazebo-specific tags-->

    <gazebo reference="pelvis">
    <material>Gazebo/Grey  </material>
    </gazebo>
    <gazebo reference="hip1_1">
        <material>Gazebo/Grey   </material>
    </gazebo>
    <gazebo reference="hip2_1">
        <material>Gazebo/SkyBlue </material>
    </gazebo>
    <gazebo reference="knee_1">
        <material>Gazebo/Grey  </material>
    </gazebo>
    
  </robot>